Traceback (most recent call last):
  File "/usr/local/lib/python3.9/dist-packages/jupyter_cache/executors/utils.py", line 58, in single_nb_execution
    executenb(
  File "/usr/local/lib/python3.9/dist-packages/nbclient/client.py", line 1204, in execute
    return NotebookClient(nb=nb, resources=resources, km=km, **kwargs).execute()
  File "/usr/local/lib/python3.9/dist-packages/nbclient/util.py", line 84, in wrapped
    return just_run(coro(*args, **kwargs))
  File "/usr/local/lib/python3.9/dist-packages/nbclient/util.py", line 62, in just_run
    return loop.run_until_complete(coro)
  File "/usr/lib/python3.9/asyncio/base_events.py", line 647, in run_until_complete
    return future.result()
  File "/usr/local/lib/python3.9/dist-packages/nbclient/client.py", line 663, in async_execute
    await self.async_execute_cell(
  File "/usr/local/lib/python3.9/dist-packages/nbclient/client.py", line 965, in async_execute_cell
    await self._check_raise_for_error(cell, cell_index, exec_reply)
  File "/usr/local/lib/python3.9/dist-packages/nbclient/client.py", line 862, in _check_raise_for_error
    raise CellExecutionError.from_cell_and_msg(cell, exec_reply_content)
nbclient.exceptions.CellExecutionError: An error occurred while executing the following cell:
------------------
import psycopg2
conn = psycopg2.connect(
    database="prosaindata{200411100055}",
    user = "postgres",
    password = "root",
    host = "localhost",
    prot = "5432"
)
cur = conn.cursor()
cur.execute("SELECT * FROM data_iris")
rows = cur.fetchall()
for row in rows:
  print(roW)
------------------

[0;31m[0m
[0;31mProgrammingError[0mTraceback (most recent call last)
[0;32m<ipython-input-1-72ca77387866>[0m in [0;36m<module>[0;34m[0m
[1;32m      1[0m [0;32mimport[0m [0mpsycopg2[0m[0;34m[0m[0;34m[0m[0m
[0;32m----> 2[0;31m conn = psycopg2.connect(
[0m[1;32m      3[0m     [0mdatabase[0m[0;34m=[0m[0;34m"prosaindata{200411100055}"[0m[0;34m,[0m[0;34m[0m[0;34m[0m[0m
[1;32m      4[0m     [0muser[0m [0;34m=[0m [0;34m"postgres"[0m[0;34m,[0m[0;34m[0m[0;34m[0m[0m
[1;32m      5[0m     [0mpassword[0m [0;34m=[0m [0;34m"root"[0m[0;34m,[0m[0;34m[0m[0;34m[0m[0m

[0;32m/usr/local/lib/python3.9/dist-packages/psycopg2/__init__.py[0m in [0;36mconnect[0;34m(dsn, connection_factory, cursor_factory, **kwargs)[0m
[1;32m    119[0m         [0mkwasync[0m[0;34m[[0m[0;34m'async_'[0m[0;34m][0m [0;34m=[0m [0mkwargs[0m[0;34m.[0m[0mpop[0m[0;34m([0m[0;34m'async_'[0m[0;34m)[0m[0;34m[0m[0;34m[0m[0m
[1;32m    120[0m [0;34m[0m[0m
[0;32m--> 121[0;31m     [0mdsn[0m [0;34m=[0m [0m_ext[0m[0;34m.[0m[0mmake_dsn[0m[0;34m([0m[0mdsn[0m[0;34m,[0m [0;34m**[0m[0mkwargs[0m[0;34m)[0m[0;34m[0m[0;34m[0m[0m
[0m[1;32m    122[0m     [0mconn[0m [0;34m=[0m [0m_connect[0m[0;34m([0m[0mdsn[0m[0;34m,[0m [0mconnection_factory[0m[0;34m=[0m[0mconnection_factory[0m[0;34m,[0m [0;34m**[0m[0mkwasync[0m[0;34m)[0m[0;34m[0m[0;34m[0m[0m
[1;32m    123[0m     [0;32mif[0m [0mcursor_factory[0m [0;32mis[0m [0;32mnot[0m [0;32mNone[0m[0;34m:[0m[0;34m[0m[0;34m[0m[0m

[0;32m/usr/local/lib/python3.9/dist-packages/psycopg2/extensions.py[0m in [0;36mmake_dsn[0;34m(dsn, **kwargs)[0m
[1;32m    165[0m [0;34m[0m[0m
[1;32m    166[0m     [0;31m# verify that the returned dsn is valid[0m[0;34m[0m[0;34m[0m[0m
[0;32m--> 167[0;31m     [0mparse_dsn[0m[0;34m([0m[0mdsn[0m[0;34m)[0m[0;34m[0m[0;34m[0m[0m
[0m[1;32m    168[0m [0;34m[0m[0m
[1;32m    169[0m     [0;32mreturn[0m [0mdsn[0m[0;34m[0m[0;34m[0m[0m

[0;31mProgrammingError[0m: invalid dsn: invalid connection option "prot"

ProgrammingError: invalid dsn: invalid connection option "prot"


